export const catchAsyncErrors = (theFunction) => {
  return (req, res, next) => {
    Promise.resolve(theFunction(req, res, next)).catch(next);
  };
};
//If promise is not resolved we will catch error and pass it to next middleware